間違えた問題 例外捕捉 可変長引数
===========================

# 可長変引数

## 以下のコードを実行すると何が表示されますか

> 正解したけど、念のため
>
> 2018/11/07

```ruby
>> x, *y = *[0, 1, 2]
=> [0, 1, 2]
>> p x, y
0
[1, 2]
=> [0, [1, 2]]
```



### 解説

多重代入の問題

右辺の「`*`」は無視して良い

左辺の`x`には、配列の最初の要素が格納される

`y`には「`*`」がついているので、残りの要素が配列として代入される



## 次のコードを実行するとどうなりますか

キーワード引数へHashオブジェクトを渡すことができます。

Hashの中身を渡す必要があるので、変数の前に`**`を付加します。

> `*`は、Arrayオブジェクトとして渡される


```ruby
>> def foo(arg1:100, arg2:200)
>>   puts arg1
>>   puts arg2
>> end
=> :foo

>> option = {arg2: 900}
=> {:arg2=>900}

>> foo arg1: 200, *option
SyntaxError: (irb):8: syntax error, unexpected *
```

キーワード引数へHashオブジェクトを渡すことができます。

Hashの中身を渡す必要があるので、変数の前に`**`を付加します。

```ruby
>> def foo(arg1:100, arg2:200)
>>   puts arg1
>>   puts arg2
>> end
=> :foo

>> option = {arg2: 900}
=> {:arg2=>900}

>> foo arg1: 200, **option    # 変数の前のオペランドを`**`に変更
200
900
=> nil
```



## 以下のコードを実行するとどうなりますか

```ruby
>> def hoge(*args, &block)
>>   block.call(*args)
>> end
=> :hoge

>> hoge(1,2,3,4) do |*args|
>>   p args.length > 0 ? "hello" : args
>> end
"hello"
=> "hello"
```



### 解説

問題のソースコード

```ruby
1: def hoge(*args, &block)
2:   block.call(*args)
3: end
4:
5: hoge(1,2,3,4) do |*args|
6:   p args.length > 0 ? "hello" : args
7: end
```

1行目で引数の値を配列として受け取り、ブロックに配列を渡しています。

2行目で`*`を付けて引数を渡しているので、配列が展開されます`(1, 2, 3, 4)`。

5行目でブロック変数を渡していますが、`*args`と宣言されているので、`[1, 2, 3, 4]`が渡されます。

6行目で`args.length > 0`の結果は真となり、`hello`が出力されます。



## 以下の実行結果になるように、`__X__`に記述する適切なコードを選びなさい

```ruby
def hoge(*args)
  p __X__
end
hoge [1, 2, 3]

# 実行結果
[1, 2, 3]
```

1. `args`

1. `*args`

1. `&args`

1. `$args`



### 解説

「`*`」の付いたメソッド引数は、可長変引数となる

`hoge`の引数`args`は配列として扱われる

`hoge`に配列`[1, 2, 3]`を渡すと、`args[0]`に渡される

したがって、実行結果を`[1, 2, 3]`にするには、

* `args[0]`

* `*args`

にする

```ruby
>> def hoge(*args)
>>   p *args
>> end
=> :hoge
>> hoge [1, 2, 3]
[1, 2, 3]
=> [1, 2, 3]
```


## 可変長引数について適切な記述を選びなさい

1. 可変長引数にデフォルト値付引数を指定できる

1. 引数はハッシュとして扱える

1. 可変長引数には`*`を付ける

1. １つのメソッドに可変長引数を複数指定することができる



### 解説

> 解答：3

可変長引数にデフォルト値は指定できない

引数は配列として扱われる

可変長引数は1つのメソッドに1つしか指定できない




## 以下の実行結果になるように、`__X__`に記述する適切なコードを選びなさい

> 正解しているが、念のため
>
> 2018/11/07

```ruby
def hoge __X__
  puts "#{x}, #{y}, #{params[:z]}"
end

hoge x: 1, z: 3

# 実行結果
1, 2, 3
```

1. `(x:, y: 2, params: *)`

1. `(x:, y: 2, *params)`

1. `(x:, y: 2, **params)`

1. `(x:, y: 2, params: **)`



### 解説

キーワード引数の中で任意の値を受け取れるようにしたい場合は、`**params`のように引数の前に`**`を繋げることで、

明示的に定義したキーワード以外の引数をHashオブジェクトで受け取ることができる

```ruby
>> def hoge (x:, y: 2, **params)
>>   puts "#{x}, #{y}, #{params[:z]}"
>> end
=> :hoge

>> hoge x: 1, z: 3
1, 2, 3
=> nil
```



### 参考

```ruby
# 配列展開なし
>> hoge(1,2,3,4) do |*args|
?> p args
>> end
[1, 2, 3, 4]
=> [1, 2, 3, 4]

# 配列展開あり
>> hoge(1,2,3,4) do |*args|
?> p *args
>> end
1
2
3
4
=> [1, 2, 3, 4]
```









# 例外処理

## 次のコードを実行するとどうなりますか

`String#+`は`String`クラスのオブジェクトを期待します。

引数に`Symbol`クラスを渡しているため`TypeError`が発生します。

> `else`ブロックは例外が発生しない場合に評価されます。
>
> 優先順位は、「エラー名指定のrescue」>「エラー名指定なしのrescue」

```ruby
>> begin
>>   print "liberty" + :fish
>> rescue TypeError
>>   print "TypeError."
>> rescue
>>   print "Error."
>> else
>>   print "Else."
>> end
TypeError.=> nil

# 検証
>> begin
>>   print "liberty" + :fish
>> rescue
>>   print "Error."
>> else
>>   print "Else."
>> end
Error.=> nil
```



## 次のコードを実行するとどうなりますか

```ruby
>> begin
>>   print "liberty" + :fish.to_s
>> rescue TypeError
>>   print "TypeError."
>> rescue
>>   print "Error."
>> else
>>   print "Else."
>> ensure
>>   print "Ensure."
>> end
libertyfishElse.Ensure.=> nil
```



### 解説

* `:fish`はSymbolクラスのオブジェクトです。

  `Symbol#to_s`でStringオブジェクトが返されます。

* `String#+`の引数はStringクラスを期待します。

  Stringクラス以外のオブジェクトが渡された場合は、`TypeError`を発生させます。

* エラーを受け取るためには`rescue`で、例外を受け取った際の処理を記述します。

* エラーが発生しなかった場合の処理を行うには`else`を用います。

* エラー発生有無に関わらず、必ず実行される、後処理を行うには`ensure`を用います。

> `print`は、改行をせずに出力する！！



## 次のコードを実行するとどうなりますか

引数なしで`raise`を呼び出すと、`RuntimeError`例外が発生します。

```ruby
>> begin
>>   raise
>> rescue => e
>>   puts e.class
>> end
RuntimeError
=> nil
```



## 次のコードを実行するとどうなりますか

`raise`の例外クラスを省略した場合は、`RuntimeError`を発生させます。

`rescue`の例外クラスを省略した場合は、`StandardError`を捕捉します。

`RuntimeError`は`StanderdError`のサブクラスです。

```ruby
>> begin
>>   raise "Err!"
>> rescue => e
>>   puts e.class
>> end
RuntimeError
=> nil
```



## 以下のコードを実行するとどうなりますか

> 正解したけど、念のため
>
> 2018/11/07

```ruby
>> class Err1 < StandardError; end
=> nil
>> class Err2 < Err1; end
=> nil

>> begin
>>   raise Err2
>> rescue => e
>>   puts "StandardError"
>> rescue Err2 => ex
>>   puts ex.class
>> end
StandardError
=> nil
```



### 解説

begin節の`raise`で発生する例外オブジェクトのクラスはErr2

2個目のrescue節ではErr2、もしくはErr2を継承した例外オブジェクトを対象とするように書かれているが、

1個目のrescue節でStandardErrorから派生する全ての例外を対象とするため、

2個目のrescue節では処理されず、1個目のrescue節で処理される



## 4行目で生成(raise)される例外オブジェクトのクラスは何ですか

```ruby
>> begin
>>   "cat".narrow        # String#narrowメソッドは存在しない
>> rescue NameError
>>   raise
>> end
NoMethodError: undefined method `narrow` for "cat":String
```



### 解説

rescue節の`raise`は、rescue節が処理中の例外オブジェクトを再生成する

オブジェクトに存在しないメソッドを実行した場合、NoMethodErrorオブジェクトが発生する

2行目でNoMethodErrorオブジェクトが発生するので、3行目以降のrescue節でキャッチしたNoMethodErrorオブジェクトが

そのままraiseされる



## 以下のコードを実行すると何が表示されますか

```ruby
begin
  exit
rescue StandardError
  puts "StandardError"
rescue SystemExit
  puts "SystemExit"
end
puts "End"
=> SystemExit
=> End
```



### 解説

組み込み関数`exit`は、例外SystemExitを発生させる

これを`rescue`すれば、実行を継続する

`rescue`しなければ、プログラムを終了する



## 以下の実行結果になるように、`__X__`に記述する適切なコードを全て選びなさい

```ruby
class Err1 < StandardError; end
class Err2 < Err1; end
begin
  __X__
rescue Err1 => e
  puts "Error"
end

# 実行結果
Error
```

1. `raise StandardError`

1. `raise Err1`

1. `raise Err2`

1. `raise`



### 解説

> 解答：2, 3

出題コードの`rescue Err1`は、

* Err1

* Err1のサブクラス(Err2)

の例外を捕捉する
