03 エラーハンドリング
=====================

## 関数の戻り値によるエラーハンドリング

* Go言語では、関数の戻り値に複数の値を返すことができる

* これを利用してエラーハンドリングを行うことができます。

  * 標準関数を含むほとんどで、2つめの戻り値にエラー情報を返している

* エラー情報には、「errorインタフェース型」を使用します。

  * `builtin`パッケージに組み込まれている型で、`Error`メソッドを利用して詳細情報を取得

```go
// エラーインタフェースの定義内容
type error interface{
  Error() string
}
```

* error型の値を返す関数では、エラーが発生しないときは`nil`が返される

```go
package main

import (
	"fmt"
  "os"
)

func main() {
  // ファイルを開く
  file, err := os.Open("test.txt")
  // エラー判定
  if err != nil {
    // 失敗
    fmt.Println(err.Error())
    } else {
    // 成功
    fmt.Println("Successful!")
    file.Close()
	}
}
```

* `err.Error()`の戻り値はstring型となる

```txt
open test.txt: no such file or directory
```



### 自作した関数のエラー処理

```go
age main

import (
	"fmt"
	"os"
)

type myAppError struct {
	msg string //エラーメッセージ
}

func (e myAppError) Error() string {
	// エラーメッセージを返す
	return e.msg
}

func testOpen() (file os.File, err error) {
	file, err := os.Open("test.txt")
	if err != nil {
		// エラーが発生したので、myAppError構造体の値を作成し、エラー情報として返す
		return nil, myAppError{"ファイルが開けません - " + err.Error()}
	}
	// 成功した場合は、error情報をnilとして返す。
	return file, nil
}

func main() {
	file, err := testOpen()
	if err != nil {
		// エラー情報が戻ってきたので、エラーとして処理する。
		fmt.Println("失敗しました。 - " + err.Error())
		os.Exit(1)
	}
	// 後略
}
```



## パニック

* 関数内でエラーが発生したとき、通常ならば呼び出し元がエラーハンドリングを行う

* 致命的なエラーのため、その必要がない場合があります。

  * `panic`という組み込み関数を呼び出して、「パニック」状態を発生させる

  * ある関数内で`panic`を呼び出すと、その関数の実行は中断され、呼び出し元に復帰する

  * 呼び出し元に復帰後も、順次関数の呼び出し元をさかのぼり、最終的にプログラム自体が終了する

  * パニック状態でプログラムが終了すると、`panic`を呼び出した箇所とともに、引数として渡したパラメータの値が標準エラー出力に出力

```go
package main

func func1() {
	panic("Occured panic!")
}

func main() {
	func1()
}
```

```txt
panic: Occured panic!

goroutine 1 [running]:
main.func1(...)
        /Users/kunii.sotaro/work/knowledge/Go/20200322_Go.go:61
main.main()
        /Users/kunii.sotaro/work/knowledge/Go/20200322_Go.go:65 +0x39
exit status 2
```



### panic実行前に指定したdefer関数

* `panic`を呼び出すと、その関数は中断される

* ただし、呼び出し前に`defer`で指定した関数は実行される

```go
package main

import "fmt"

func func1() {
	defer func() {
		fmt.Println("defer 2")
	}()
	panic("Occured panic!")
}

func main() {
	defer func() {
		fmt.Println("defer 1")
	}()
	func1()
}
```

```txt
defer 2
defer 1
panic: Occured panic!

goroutine 1 [running]:
main.func1()
        /Users/kunii.sotaro/work/knowledge/Go/20200322_Go.go:76 +0x5b
main.main()
        /Users/kunii.sotaro/work/knowledge/Go/20200322_Go.go:83 +0x44
exit status 2
```



### ランタイムパニック

* `ランタイムパニック`:インデックスの超過など、Go言語のランタイムがパニックを起こすこと

  * このときには「`runtime.Error`インタフェース」が渡される

```go
// runtime.Errorインタフェースの定義内容
package runtime
type Error interface {
	error

	RuntimeError()
}
```

* ランタイムパニックは、次の様にして確認することができる

```go
package main

func main() {
	arr := [...]int{1, 2, 3}

	index := 3

	arr[index] = 0
}
```

```txt
panic: runtime error: index out of range [3] with length 3

goroutine 1 [running]:
main.main()
        /Users/kunii.sotaro/work/knowledge/Go/20200322_Go.go:93 +0x1b
exit status 2
```



## リカバリ

* `panic`を呼び出して、関数をさかのぼる途中に`recover`を呼び出すことで、パニック状態を中断させることが可能

  * `recovery`の戻り値は、`panic`に与えた引数なので、パニック状態ではない場合は`nil`

  * これを利用して、現在パニック状態なのか、そうではないのかを判断可能

* ただし`recover`を呼び出すことができるのは、`defer`によって遅延指定された関数内だけ

  * これはパニック状態で呼び出される可能性がある関数は、`defer`で指定された関数のみのため

```go
package main

import "fmt"

func func1(b bool) {
	defer func() {
		fmt.Println("defer start.")

		if err := recover(); err != nil {
		    // パニック中だった
			fmt.Println("recovery!")
		}
		fmt.Println("defer end.")
	}()
	if b {
		panic("Occure panic!")
	}
}

func main() {
	func1(false)
	func1(true)
}
```

```txt
defer start.
defer end.
defer start.
recovery!
defer end.
```
