11 脱出構文と例外処理、大域脱出
===========================

## 目次

* [脱出構文と大域脱出とは](#脱出構文と大域脱出とは)

* [脱出構文](#3-11-1.脱出構文)

* [例外処理](#3-11-2.例外処理)

* [例外クラスを指定した捕捉](#3-11-3.例外クラスを指定した捕捉)

* [catch&throwによる大域脱出](#3-11-4.catch&throwによる大域脱出)



## 脱出構文と大域脱出とは

* `脱出構文`：ループを抜ける。指定した場合の実行順序が重要。

* `大域脱出`：メソッドを抜ける。構文が重要。



## 3-11-1.脱出構文

### ループ中の現在の回を中断するための構文

* `break`：ループそのものを中断する

* `next`：他のプログラミングで`continue`に値する

* `redo`：現在の処理をやり直す



### `next`と`redo`の違い

ループ条件の評価などを再度行うかどうかが異なる

* `next`：中断して次の回に進む

* `redo`：現在の回を繰り返す

```ruby
# nextメソッド
>> 10.times do |i|
?>   next if i == 5   # iが5の時、nextが実行されて次のループに進む
>>   print i, " "
>> end
0 1 2 3 4 6 7 8 9 => 10

# redoメソッド
>> 10.times do |i|
?>   redo if i == 5   # iが5のループをやり直すが、iは5のまま変わらないので、無限ループになる
>>   print i, " "
>> end
0 1 2 3 4  # 0 1 2 3 4 と表示された後、無限ループ
```



## 3-11-2.例外処理

* 例外を発生させるためには、`raise`を使用

> `Kernel.#raise`

* 第1引数に`例外クラス`or`そのインスタンス`、第2引数に`メッセージ`を指定

```ruby
>> raise ArgumentError, "引数が不正です"
ArgumentError: 引数が不正です

>> raise ArgumentError.new, "引数が不正です"
ArgumentError: 引数が不正です
```

* 例外クラスのコンストラクタでは、メッセージを指定できる

```ruby
>> err = ArgumentError.new("引数が不正です")
=> #<ArgumentError: 引数が不正です>
>> raise err
ArgumentError: 引数が不正です
```



### 引数を省略した場合の例外

* `例外クラス`のインスタンスのみ、あるいは **メッセージ** のみを記述可能

* `例外クラス`のインスタンスを省略した場合は、`RuntimeError`クラスの例外が発生する

```ruby
>> raise "実行中にエラーが発生しました"
RuntimeError: 実行中にエラーが発生しました
```



### 例外処理

* 例外が発生した場合は、そこで処理が中断する

* 処理を中断せずに続行する際に、 **例外処理** を記述する必要がある。

  * 例外が発生する可能性がある箇所を、`begin`と`end`で囲む

  * その中の`rescue`という節で、 **例外処理** を記述する

```ruby
>> begin
?>   1/0
>>   p 1
>> rescue
>>   p 0    # 例外処理。0が出力される
>> end
0
=> 0
```

* `rescue`節に続いて`else`節を指定することで、例外が発生しなかった時の処理を記述できる

* `ensure`節を続けることで、例外の発生に関わらず、必ず実行する処理も記述できる

```ruby
>> begin    # begin節は実行される
?>   p 1
>> rescue   # 例外は発生しないので、実行されない
>>   p 0
>> else     # rescue節が実行されないので、else節は実行される
?>   p 2
>> ensure   # ensure節は必ず実行される
?>   p 3
>> end
1
2
3
=> 2
```

* `rescue`は、`begin`節を指定しなくても使用できる

* `rescue`節は、if式と同様に修飾子として書くこともできる

  > 例外が発生すると、`rescue`で指定された式が実行される

```ruby
>> 1 / 0 rescue p 1
1
=> 1

# メソッドの中で指定
>> def foo
>>   -1 / 0
>> rescue    # メソッドの内部で例外が発生すると、rescue以降を実行
>>   p 1
>> end
=> :foo
>> foo
1
=> 1
```



## 3-11-3.例外クラスを指定した捕捉

### 例外クラスの階層構造

* `Exception`

  * `ScriptError`

    * `SyntaxError`：文法エラーがあった場合

  * `SignalException`：捕捉していないシグナルを受けた場合

  * `StandardError`

    * `ArgumentError`：引数の数が合わない場合or値が正しくない場合

    * `RuntimeError`：特定した例外クラスには該当しないエラーが発生した場合or例外クラスを省略した`raise`の呼び出し

    * `TypeError`：添字が範囲外の場合

    * `NameError`：未定義のローカル変数や定数を参照した場合

      * `NoMethodError`：未定義のメソッドを呼び出した場合

  * `ZeroDivisionError`：整数に対し、整数の0で除算を行なった場合



### 例外オブジェクトの取得

* 各例外クラスを`rescue`に続けて指定することで、それ自身orそのサブクラスを捕捉できる

* 例外クラスに続いて`=>`で識別子を指定すると、例外オブジェクトを参照できる

  * `message`メソッド：指定した例外メッセージを参照

  * `backtrace`メソッド：例外が発生した場所を参照


```ruby
>> begin
?> 1/0
>> rescue ZeroDivisionError => e
>> p e.backtrace
>> end
["(irb):2:in `/'", "(irb):2:in `irb_binding'", "/Users/MacUser/.rbenv/versions/2.4.1/lib/ruby/2.4.0/irb/workspace.rb:87:in `eval'",] # 省略
```



### 例外の再発生

* 同じスレッドとブロックで発生した最後の例外は、組み込み変数`$!`で参照可能

* さらに、`raise`メソッドを引数なしで実行することで、最後に発生した例外を再度発生させることができる

  > 責任範囲でやるべきことを行い、残りを呼び出し先に委ねる場合に便利

```ruby
>> begin
?> 1/0
>> rescue ZeroDivisionError
>> p $!.class
>> raise
>> end
ZeroDivisionError
ZeroDivisionError: divided by 0
```

* 例外処理を呼び出し元に委ねるのではなく、自分で解決する際に`retry`を使用

  > `retry`：再度`begin`節を実行。`ensure`節は1回のみ実行

```ruby
=> 0
>> begin
?>   b = 1/a
>> rescue ZeroDivisionError
>>   a += 1
>> retry
>> ensure    # 必ず行われる部分
?>   p b
>> end
1
=> 1
```



### `ensure`節の実行順

* `rescue`節は１つの`begin`節の中でいくつでも指定可能

* ただし、最初にマッチしたものしか実行されない

* より範囲の狭い例外クラスを指定しても、役に立たないことが多いので、 **マッチする範囲が広くなる順に指定する**

```ruby
>> begin 1/0
>> rescue     # 最初にマッチしたもの、出力される
>>   p 1
>> rescue ZeroDivisionError
>>   p 2
>> end
1
=> 1
```



## 3-11-4.catch&throwによる大域脱出

繰り返しの処理を途中で終了する場合、`break`を使うことがある。

しかし繰り返しの処理がネストしているかつ、一度に処理を終了させたい場合がある。

繰り返しの処理のネストが深い場合、そのネスト分の`break`が必要である。

* `catch`&`throw`：階層の深いループの中で全ての処理が完了した場合のように、正常時であっても処理を抜けたい場合に使用

```ruby
>> def foo
>>   throw :exit
>> end
=> :foo
>>
?> catch(:exit) {
?>   foo
>>   p 1  # 実行されない
>> }
=> nil
>> p 2
2
=> 2
```

* `loop`：無限ループするメソッド

* `throw`が例外の場合の`raise`、`catch`が`begin`節に相当する

* `throw`が実行されると、同名のラベルが指定されている`catch`まで呼び出しタスクを辿る

  * 見つかった場合は、そのブロック内における後続の処理をスキップ

* ラベルには、シンボルの他に文字列が指定できる。対応するラベルが見つからない場合は、`NameError`が発生

```ruby
>> def bar
>>   catch(:calc) do
?>     throw :calc, 100
>>   end
>> end
=> :bar
>> p bar
100
=> 100
```

* `throw`にはラベル以外に値を引数として渡すことができる

* `throw`に渡した値は、`catch`の戻り値とすることができる



| 版     | 日付       |
| ------ | ---------- |
| 初版   | 2018/08/19 |
| 第二版 | 2018/10/04 |
| 第三版 | 2019/05/11 |
